Workbook

Sheet Summary
A1: APX vetting scenarios by module
A2: Private. Built from test-scenarios/apx-*.md against APX v0.11.0 (LPR re-vetted against v0.12.1 on 2026-09-28). Each module has its own tab; counts below are formulas over those tabs.
A4: Module | B4: OpenAPI tags | C4: Scenarios | D4: Happy | E4: Refusal | F4: Lifecycle | G4: Security | H4: Edge | I4: Exchanges | J4: With open gap
A5: apx-accounts | B5: Accounts | C5: =COUNTA('apx-accounts'!A:A)-1 | D5: =COUNTIF('apx-accounts'!C:C,"happy") | E5: =COUNTIF('apx-accounts'!C:C,"refusal") | F5: =COUNTIF('apx-accounts'!C:C,"lifecycle") | G5: =COUNTIF('apx-accounts'!C:C,"security") | H5: =COUNTIF('apx-accounts'!C:C,"edge") | I5: =SUM('apx-accounts'!G:G) | J5: =COUNTIF('apx-accounts'!H:H,"?*")
A6: apx-alerts | B6: Alerts | C6: =COUNTA('apx-alerts'!A:A)-1 | D6: =COUNTIF('apx-alerts'!C:C,"happy") | E6: =COUNTIF('apx-alerts'!C:C,"refusal") | F6: =COUNTIF('apx-alerts'!C:C,"lifecycle") | G6: =COUNTIF('apx-alerts'!C:C,"security") | H6: =COUNTIF('apx-alerts'!C:C,"edge") | I6: =SUM('apx-alerts'!G:G) | J6: =COUNTIF('apx-alerts'!H:H,"?*")
A7: apx-control | B7: Control | C7: =COUNTA('apx-control'!A:A)-1 | D7: =COUNTIF('apx-control'!C:C,"happy") | E7: =COUNTIF('apx-control'!C:C,"refusal") | F7: =COUNTIF('apx-control'!C:C,"lifecycle") | G7: =COUNTIF('apx-control'!C:C,"security") | H7: =COUNTIF('apx-control'!C:C,"edge") | I7: =SUM('apx-control'!G:G) | J7: =COUNTIF('apx-control'!H:H,"?*")
A8: apx-credentials | B8: Credentials | C8: =COUNTA('apx-credentials'!A:A)-1 | D8: =COUNTIF('apx-credentials'!C:C,"happy") | E8: =COUNTIF('apx-credentials'!C:C,"refusal") | F8: =COUNTIF('apx-credentials'!C:C,"lifecycle") | G8: =COUNTIF('apx-credentials'!C:C,"security") | H8: =COUNTIF('apx-credentials'!C:C,"edge") | I8: =SUM('apx-credentials'!G:G) | J8: =COUNTIF('apx-credentials'!H:H,"?*")
A9: apx-data | B9: Data, Places, Sessions, Rate Tables, Assigned Rights, Right Specifications, Observation, Organisations, Quote | C9: =COUNTA('apx-data'!A:A)-1 | D9: =COUNTIF('apx-data'!C:C,"happy") | E9: =COUNTIF('apx-data'!C:C,"refusal") | F9: =COUNTIF('apx-data'!C:C,"lifecycle") | G9: =COUNTIF('apx-data'!C:C,"security") | H9: =COUNTIF('apx-data'!C:C,"edge") | I9: =SUM('apx-data'!G:G) | J9: =COUNTIF('apx-data'!H:H,"?*")
A10: apx-discovery | B10: Discovery | C10: =COUNTA('apx-discovery'!A:A)-1 | D10: =COUNTIF('apx-discovery'!C:C,"happy") | E10: =COUNTIF('apx-discovery'!C:C,"refusal") | F10: =COUNTIF('apx-discovery'!C:C,"lifecycle") | G10: =COUNTIF('apx-discovery'!C:C,"security") | H10: =COUNTIF('apx-discovery'!C:C,"edge") | I10: =SUM('apx-discovery'!G:G) | J10: =COUNTIF('apx-discovery'!H:H,"?*")
A11: apx-events | B11: Subscription | C11: =COUNTA('apx-events'!A:A)-1 | D11: =COUNTIF('apx-events'!C:C,"happy") | E11: =COUNTIF('apx-events'!C:C,"refusal") | F11: =COUNTIF('apx-events'!C:C,"lifecycle") | G11: =COUNTIF('apx-events'!C:C,"security") | H11: =COUNTIF('apx-events'!C:C,"edge") | I11: =SUM('apx-events'!G:G) | J11: =COUNTIF('apx-events'!H:H,"?*")
A12: apx-lpr | B12: LPR | C12: =COUNTA('apx-lpr'!A:A)-1 | D12: =COUNTIF('apx-lpr'!C:C,"happy") | E12: =COUNTIF('apx-lpr'!C:C,"refusal") | F12: =COUNTIF('apx-lpr'!C:C,"lifecycle") | G12: =COUNTIF('apx-lpr'!C:C,"security") | H12: =COUNTIF('apx-lpr'!C:C,"edge") | I12: =SUM('apx-lpr'!G:G) | J12: =COUNTIF('apx-lpr'!H:H,"?*")
A13: apx-permits | B13: Permits | C13: =COUNTA('apx-permits'!A:A)-1 | D13: =COUNTIF('apx-permits'!C:C,"happy") | E13: =COUNTIF('apx-permits'!C:C,"refusal") | F13: =COUNTIF('apx-permits'!C:C,"lifecycle") | G13: =COUNTIF('apx-permits'!C:C,"security") | H13: =COUNTIF('apx-permits'!C:C,"edge") | I13: =SUM('apx-permits'!G:G) | J13: =COUNTIF('apx-permits'!H:H,"?*")
A14: apx-reservations | B14: Reservations | C14: =COUNTA('apx-reservations'!A:A)-1 | D14: =COUNTIF('apx-reservations'!C:C,"happy") | E14: =COUNTIF('apx-reservations'!C:C,"refusal") | F14: =COUNTIF('apx-reservations'!C:C,"lifecycle") | G14: =COUNTIF('apx-reservations'!C:C,"security") | H14: =COUNTIF('apx-reservations'!C:C,"edge") | I14: =SUM('apx-reservations'!G:G) | J14: =COUNTIF('apx-reservations'!H:H,"?*")
A15: apx-resolution | B15: Resolution, Support | C15: =COUNTA('apx-resolution'!A:A)-1 | D15: =COUNTIF('apx-resolution'!C:C,"happy") | E15: =COUNTIF('apx-resolution'!C:C,"refusal") | F15: =COUNTIF('apx-resolution'!C:C,"lifecycle") | G15: =COUNTIF('apx-resolution'!C:C,"security") | H15: =COUNTIF('apx-resolution'!C:C,"edge") | I15: =SUM('apx-resolution'!G:G) | J15: =COUNTIF('apx-resolution'!H:H,"?*")
A16: apx-tolling | B16: Tolling | C16: =COUNTA('apx-tolling'!A:A)-1 | D16: =COUNTIF('apx-tolling'!C:C,"happy") | E16: =COUNTIF('apx-tolling'!C:C,"refusal") | F16: =COUNTIF('apx-tolling'!C:C,"lifecycle") | G16: =COUNTIF('apx-tolling'!C:C,"security") | H16: =COUNTIF('apx-tolling'!C:C,"edge") | I16: =SUM('apx-tolling'!G:G) | J16: =COUNTIF('apx-tolling'!H:H,"?*")
A17: apx-valet | B17: Valet | C17: =COUNTA('apx-valet'!A:A)-1 | D17: =COUNTIF('apx-valet'!C:C,"happy") | E17: =COUNTIF('apx-valet'!C:C,"refusal") | F17: =COUNTIF('apx-valet'!C:C,"lifecycle") | G17: =COUNTIF('apx-valet'!C:C,"security") | H17: =COUNTIF('apx-valet'!C:C,"edge") | I17: =SUM('apx-valet'!G:G) | J17: =COUNTIF('apx-valet'!H:H,"?*")
A18: apx-validations | B18: Validations | C18: =COUNTA('apx-validations'!A:A)-1 | D18: =COUNTIF('apx-validations'!C:C,"happy") | E18: =COUNTIF('apx-validations'!C:C,"refusal") | F18: =COUNTIF('apx-validations'!C:C,"lifecycle") | G18: =COUNTIF('apx-validations'!C:C,"security") | H18: =COUNTIF('apx-validations'!C:C,"edge") | I18: =SUM('apx-validations'!G:G) | J18: =COUNTIF('apx-validations'!H:H,"?*")
A19: apx-violations | B19: Violations | C19: =COUNTA('apx-violations'!A:A)-1 | D19: =COUNTIF('apx-violations'!C:C,"happy") | E19: =COUNTIF('apx-violations'!C:C,"refusal") | F19: =COUNTIF('apx-violations'!C:C,"lifecycle") | G19: =COUNTIF('apx-violations'!C:C,"security") | H19: =COUNTIF('apx-violations'!C:C,"edge") | I19: =SUM('apx-violations'!G:G) | J19: =COUNTIF('apx-violations'!H:H,"?*")
A20: Total | C20: =SUM(C5:C19) | D20: =SUM(D5:D19) | E20: =SUM(E5:E19) | F20: =SUM(F5:F19) | G20: =SUM(G5:G19) | H20: =SUM(H5:H19) | I20: =SUM(I5:I19) | J20: =SUM(J5:J19)
A22: Kinds: happy = the intended path; refusal = the server correctly says no; lifecycle = a state machine walked through its transitions; security = scopes, grants, tokens; edge = retries, limits, and unusual inputs. 'With open gap' counts scenarios still citing an unfixed spec finding (F-RSV-02, an upstream APDS defect with no additive workaround).

Sheet apx-accounts
A1: ID | B1: Title | C1: Kind | D1: Annex A rows | E1: Scenario (Given / When / Then) | F1: Exchanges (request → status) | G1: Exchange count | H1: Open spec gap
A2: ACC-01 | B2: A monthly parker calls in: lookup by phone | C2: happy | D2: APX-ACC-01 | E2: Given J. Smith calls the operator's number from the phone on file. When the console looks the caller up by phone before the agent answers. Then 200 with one account, its balance and status, and the place it is valid at, so the greeting can be "Hi J., I see $185 owing at Lakeside". | F2: GET /v1/accounts → 200 | G2: =IF(F2="",0,LEN(F2)-LEN(SUBSTITUTE(F2,CHAR(10),""))+1)
A3: ACC-02 | B3: Every other key: plate, card, name, a combination, by id, and the ones that are not there | C3: happy | D3: APX-ACC-01 | E3: Given callers who know only their plate, only their access card, or only their name. When the console tries each filter, then narrows a common surname with a plate, then fetches by id. Then each lookup returns the matching accounts, an unknown plate returns an empty list, and an unknown id is 404. The email key and the §13.5(3) place narrowing are declared (F-ACC-09, F-ACC-08 fixed), and Account.email comes back under apx.accounts:read. | F3: GET /v1/accounts → 200 GET /v1/accounts → 200 GET /v1/accounts → 200 GET /v1/accounts → 200 GET /v1/accounts/c2000000-0000-4000-8000-000000000004 → 200 GET /v1/accounts/c2000000-0000-4000-8000-0000000000ff → 404 GET /v1/accounts → 200 GET /v1/accounts → 200 GET /v1/accounts → 200 | G3: =IF(F3="",0,LEN(F3)-LEN(SUBSTITUTE(F3,CHAR(10),""))+1)
A4: ACC-03 | B4: The grant, not the scope, bounds a place-less lookup | C4: security | D4: APX-ACC-01, APX-CORE-07, APX-CORE-08 | E4: Given J. Smith holds accounts at both Lakeside and Harbor Deck under the same plate. When a token granted only Lakeside searches the plate, an all-places token searches it, and a token with no apx_places claim searches it. Then the first sees only the Lakeside account, the second sees both, and the third sees nothing (fail-closed; whether that is an empty 200 or a 403 is F-ACC-13). Fetching the Harbor account by id with the Lakeside token is 403 insufficient-grant, which the operation does not declare (F-ACC-02). | F4: GET /v1/accounts → 200 GET /v1/accounts → 200 GET /v1/accounts → 200 GET /v1/accounts/c2000000-0000-4000-8000-000000000006 → 403 | G4: =IF(F4="",0,LEN(F4)-LEN(SUBSTITUTE(F4,CHAR(10),""))+1)
A5: ACC-04 | B5: The wrong scope on every route | C5: refusal | D5: APX-CORE-07 | E5: Given a payments-only token (apx.payments:write) and a read-only token (apx.accounts:read). When the payments token reads accounts and payment history, and the read token takes a payment and voids one. Then each is 403 insufficient-scope; nothing is read or moved. | F5: GET /v1/accounts → 403 GET /v1/payments → 403 POST /v1/payments → 403 POST /v1/payments/e8000000-0000-4000-8000-000000000205/void → 403 | G5: =IF(F5="",0,LEN(F5)-LEN(SUBSTITUTE(F5,CHAR(10),""))+1)
A6: ACC-05 | B6: Pay the balance over the IVR; the balance drops; the event lands | C6: happy | D6: APX-ACC-02, APX-ACC-03 | E6: Given J. Smith agrees to pay the $185.00 and is transferred to the PCI-compliant IVR, which captures the card out of band. When the console records the payment with method: autoAttendant and an idempotency key. Then 201 with a PaymentRecord bound to Lakeside, carrying a transactionID and only the last four digits; the account re-read shows a zero balance and a bumped version; and apx.accounts.payment.recorded.v1 is published with the record as data. | F6: POST /v1/payments → 201 GET /v1/accounts/c2000000-0000-4000-8000-000000000004 → 200 | G6: =IF(F6="",0,LEN(F6)-LEN(SUBSTITUTE(F6,CHAR(10),""))+1)
A7: ACC-06 | B7: The IVR bridge retries: same key, same body | C7: edge | D7: APX-ACC-02 | E7: Given the 201 from ACC-05 was lost between the IVR bridge and the console. When the bridge retries with the identical key and body. Then 200 with the ORIGINAL record; J. Smith is not charged twice and the balance stays at zero. | F7: POST /v1/payments → 200 | G7: =IF(F7="",0,LEN(F7)-LEN(SUBSTITUTE(F7,CHAR(10),""))+1)
A8: ACC-07 | B8: Same key with a different amount; no key; nothing to settle | C8: refusal | D8: APX-ACC-02, APX-CORE-05 | E8: Given three broken clients. When one reuses cc-8101-pay for a different amount, one omits Idempotency-Key, and one sends a place and an amount with neither account nor ticketNumber. Then 409 idempotency-conflict, 400 idempotency-key-required, and a 400 the operation describes ("no account/ticket to settle") but Part 12 has no slug for (F-ACC-03). | F8: POST /v1/payments → 409 POST /v1/payments → 400 POST /v1/payments → 400 | G8: =IF(F8="",0,LEN(F8)-LEN(SUBSTITUTE(F8,CHAR(10),""))+1)
A9: ACC-08 | B9: Declined at the exit lane, and the decline is a record too | C9: refusal | D9: APX-ACC-02, APX-ACC-03 | E9: Given the transient parker on ticket T-61077 reads a card to the agent after the lane terminal declined it twice. When the agent takes $18.00 by card. Then 422 payment-declined; the declined attempt is nonetheless recorded (it is what the resolution context's payments[] overlay shows) and published on apx.accounts.payment.recorded.v1 with paymentStatus: declined. The problem body points at that record through the payment extension member §13.1 now names (F-ACC-11 fixed). | F9: POST /v1/payments → 422 | G9: =IF(F9="",0,LEN(F9)-LEN(SUBSTITUTE(F9,CHAR(10),""))+1)
A10: ACC-09 | B10: A ticket payment with the accounting write-back | C10: happy | D10: APX-ACC-02, APX-ACC-03 | E10: Given the lost-ticket parker from scenario 04 owes $4.50 more on T-1001. When the agent takes it by card and then posts the payment to PARIS. Then 201 with the PaymentRecord, 201 with the Posting (a ticket payment updates no account, so accountUpdated is false), and a posting against a payment id that never existed is 404. | F10: POST /v1/payments → 201 POST /v1/payments/e8000000-0000-4000-8000-000000000202/postings → 201 POST /v1/payments/e8000000-0000-4000-8000-0000000000ff/postings → 404 POST /v1/payments/e8000000-0000-4000-8000-000000000201/postings → 201 | G10: =IF(F10="",0,LEN(F10)-LEN(SUBSTITUTE(F10,CHAR(10),""))+1)
A11: ACC-10 | B11: Posting a declined payment | C11: refusal | D11: APX-ACC-02, APX-ACC-05 | E11: Given a reconciliation script that posts every PaymentRecord it sees. When it posts the declined attempt from ACC-08. Then 409 payment-state-illegal: nothing was collected, and only an approved payment can be posted (§13.1a; F-ACC-04 fixed). | F11: POST /v1/payments/e8000000-0000-4000-8000-000000000203/postings → 409 | G11: =IF(F11="",0,LEN(F11)-LEN(SUBSTITUTE(F11,CHAR(10),""))+1)
A12: ACC-11 | B12: Declined at the exit: the payment link of first resort | C12: happy | D12: APX-ACC-04, APX-ACC-03 | E12: Given the resolution context for T-61077 lists "send payment link" as the allowed action and vending the gate as not allowed. When the agent sends an SMS link with no amount (charge the current amount due). Then 201 with the link in sent; GET /v1/payment-links/{id} shows it opened; a replay of the same key returns the link in its current representation (Part 4 §4.2a); the driver pays with a different card and the payment arrives on apx.accounts.payment.recorded.v1 (F-ACC-06 fixed). | F12: POST /v1/payment-links → 201 GET /v1/payment-links/e6000000-0000-4000-8000-000000000052 → 200 POST /v1/payment-links → 200 | G12: =IF(F12="",0,LEN(F12)-LEN(SUBSTITUTE(F12,CHAR(10),""))+1)
A13: ACC-12 | B13: Payment-link refusals | C13: refusal | D13: APX-ACC-04, APX-CORE-05 | E13: Given three more broken clients. When one sends a link with no account, ticket, or session; one asks for channel fax; and one reuses ctx-e5000000-0012-paylink for a different ticket. Then 400 invalid-request for nothing to settle, 422 request-unprocessable for the channel (§13.1a; F-ACC-03 fixed), and 409 idempotency-conflict. | F13: POST /v1/payment-links → 400 POST /v1/payment-links → 422 POST /v1/payment-links → 409 | G13: =IF(F13="",0,LEN(F13)-LEN(SUBSTITUTE(F13,CHAR(10),""))+1)
... A27: ACC-26 | B27: The shared responses on the remaining routes | C27: edge | D27: APX-CORE-05, APX-CORE-06, APX-CORE-07 | E27: Given the console from ACC-23 (rate-limited), ACC-24 (expired token), and a read-only reporting token (apx.accounts:read only). When each hits the routes the earlier scenarios did not. Then the shared 401, 403, 429, and 400 responses every secured operation declares (Part 12 §12.3). | F27: GET /v1/accounts/c2000000-0000-4000-8000-000000000004 → 401 GET /v1/accounts/c2000000-0000-4000-8000-000000000004 → 429 POST /v1/payments/e8000000-0000-4000-8000-000000000201/postings → 401 POST /v1/payments/e8000000-0000-4000-8000-000000000201/postings → 403 POST /v1/payments/e8000000-0000-4000-8000-000000000201/postings → 429 POST /v1/payments/e8000000-0000-4000-8000-000000000201/postings → 400 POST /v1/payments/e8000000-0000-4000-8000-000000000206/void → 400 POST /v1/payments/e8000000-0000-4000-8000-000000000205/capture → 400 GET /v1/payment-links/e6000000-0000-4000-8000-000000000303 → 401 GET /v1/payment-links/e6000000-0000-4000-8000-000000000303 → 429 POST /v1/payment-links/e6000000-0000-4000-8000-000000000304/cancel → 401 POST /v1/payment-links/e6000000-0000-4000-8000-000000000304/cancel → 429 | G27: =IF(F27="",0,LEN(F27)-LEN(SUBSTITUTE(F27,CHAR(10),""))+1)

Sheet apx-alerts
A1: ID | B1: Title | C1: Kind | D1: Annex A rows | E1: Scenario (Given / When / Then) | F1: Exchanges (request → status) | G1: Exchange count | H1: Open spec gap
A2: ALT-01 | B2: The intercom is pressed at exit lane 2 | C2: happy | D2: APX-ALT-02, APX-ALT-03 | E2: Given a driver presses the intercom at exit lane 2 and the lane controller integrates with the alert plane. When it raises an intercomRequest with an idempotency key, the intercom as source.device and the lane as source.place. Then 201 with the full alert in raised, one history entry, provenance in recordInfo; subscribers receive apx.alert.raised.v1 with the same alert as data; and a read by id returns it unchanged. | F2: POST /v1/alerts → 201 GET /v1/alerts/e7000000-0000-4000-8000-000000000701 → 200 | G2: =IF(F2="",0,LEN(F2)-LEN(SUBSTITUTE(F2,CHAR(10),""))+1)
A3: ALT-02 | B3: The lane controller retries: same key, same body, before and after acknowledgement | C3: edge | D3: APX-ALT-02, APX-ALT-01 | E3: Given the 201 from ALT-01 never reached the lane controller. When it replays the identical key and body; the agent then picks up the intercom and acknowledges; and a late duplicate arrives after that. Then the first replay is 200 with the original alert, the acknowledgement is 200 at version 2, and the late replay is 200 again — no second alert exists. The late replay returns the alert as it now stands, acknowledged at version 2 (Part 4 §4.2a, Part 7 §7.2; F-ALT-09 fixed). | F3: POST /v1/alerts → 200 POST /v1/alerts/e7000000-0000-4000-8000-000000000701/acknowledge → 200 POST /v1/alerts → 200 | G3: =IF(F3="",0,LEN(F3)-LEN(SUBSTITUTE(F3,CHAR(10),""))+1)
A4: ALT-03 | B4: Same key, different body; and no key at all | C4: refusal | D4: APX-ALT-02, APX-CORE-05 | E4: Given a firmware bug reuses the intercom key for a second press on the entry lane, and a second device omits the header entirely. When both POST. Then 409 idempotency-conflict for the reused key and 400 idempotency-key-required for the missing one; neither raises anything. | F4: POST /v1/alerts → 409 POST /v1/alerts → 400 | G4: =IF(F4="",0,LEN(F4)-LEN(SUBSTITUTE(F4,CHAR(10),""))+1)
A5: ALT-04 | B5: Alerts the schema refuses: a made-up severity, no detection time | C5: refusal | D5: APX-ALT-03, APX-CORE-05 | E5: Given two integrators reading the schema loosely. When one sends severity: urgent (severity is CLOSED) and one omits detectionTime. Then both are 400 invalid-request, with errors[] naming the field (Part 12 §12.4; F-ALT-05 fixed). | F5: POST /v1/alerts → 400 POST /v1/alerts → 400 | G5: =IF(F5="",0,LEN(F5)-LEN(SUBSTITUTE(F5,CHAR(10),""))+1)
A6: ALT-05 | B6: Pay station 3 faults: auto-raised, acknowledged, resolved | C6: lifecycle | D6: APX-ALT-01, APX-ALT-03 | E6: Given pay station 3 transitions to fault on the Control plane (Part 6 §6.4 says that SHOULD auto-raise a deviceFault). When the server raises it, the agent acknowledges it, and the field tech resolves it two hours later. Then subscribers see one apx.alert.raised.v1 and two apx.alert.status.v1 events, version climbs 1 → 2 → 3, and the history is only ever appended to. No client POSTed the raise. | F6: POST /v1/alerts/e7000000-0000-4000-8000-000000000702/acknowledge → 200 POST /v1/alerts/e7000000-0000-4000-8000-000000000702/resolve → 200 | G6: =IF(F6="",0,LEN(F6)-LEN(SUBSTITUTE(F6,CHAR(10),""))+1)
A7: ALT-06 | B7: Lane blocked and cleared on the spot: raised straight to resolved | C7: lifecycle | D7: APX-ALT-01 | E7: Given a stalled car in exit lane 2 and an attendant already walking over. When the lane raises laneBlocked at critical and, four minutes later, the attendant resolves it without anyone having acknowledged. Then 201, then 200 in resolved at version 2 with a two-entry history. Part 7 §7.3 permits raised → resolved directly; no acknowledgement is required. | F7: POST /v1/alerts → 201 POST /v1/alerts/e7000000-0000-4000-8000-000000000703/resolve → 200 | G7: =IF(F7="",0,LEN(F7)-LEN(SUBSTITUTE(F7,CHAR(10),""))+1)
A8: ALT-07 | B8: Transitions the state machine forbids | C8: refusal | D8: APX-ALT-01, APX-CORE-05 | E8: Given the intercom alert is acknowledged (ALT-02) and the pay-station alert is resolved (ALT-05). When a console acknowledges the acknowledged one, acknowledges the resolved one, and resolves the resolved one. Then each is 409 alert-transition-illegal and nothing changes — terminal states never transition (F-ALT-01 fixed). | F8: POST /v1/alerts/e7000000-0000-4000-8000-000000000701/acknowledge → 409 POST /v1/alerts/e7000000-0000-4000-8000-000000000702/acknowledge → 409 POST /v1/alerts/e7000000-0000-4000-8000-000000000702/resolve → 409 | G8: =IF(F8="",0,LEN(F8)-LEN(SUBSTITUTE(F8,CHAR(10),""))+1)
A9: ALT-08 | B9: An id that does not exist | C9: refusal | D9: APX-ALT-01 | E9: Given a console holding a stale id from a purged alert. When it reads, acknowledges, and resolves that id. Then 404 target-not-found on all three; every Alerts route declares 404 (F-ALT-02 fixed). | F9: GET /v1/alerts/e7000000-0000-4000-8000-000000000fff → 404 POST /v1/alerts/e7000000-0000-4000-8000-000000000fff/acknowledge → 404 POST /v1/alerts/e7000000-0000-4000-8000-000000000fff/resolve → 404 | G9: =IF(F9="",0,LEN(F9)-LEN(SUBSTITUTE(F9,CHAR(10),""))+1)
A10: ALT-09 | B10: An occupancy alert nobody touched expires on its own | C10: lifecycle | D10: APX-ALT-01, APX-ALT-03, APX-ALT-04 | E10: Given the occupancy engine raises occupancyThresholdExceeded when Lakeside crosses 95 percent, asking for a sixty-minute window with expiryTime. When nobody acknowledges it and occupancy falls back. Then at expiryTime the server moves it to expired, publishes apx.alert.status.v1, and a late acknowledge is 409. Every reader sees when the alert will lapse (Part 7 §7.3; F-ALT-03 fixed). | F10: POST /v1/alerts → 201 GET /v1/alerts/e7000000-0000-4000-8000-000000000704 → 200 POST /v1/alerts/e7000000-0000-4000-8000-000000000704/acknowledge → 409 | G10: =IF(F10="",0,LEN(F10)-LEN(SUBSTITUTE(F10,CHAR(10),""))+1)
A11: ALT-10 | B11: The ops board: what is open, what is serious, and the subtree rule | C11: happy | D11: APX-ALT-03 | E11: Given at 19:00 two alerts are open at Lakeside, both sourced on lanes: a major deviceFault on the exit gate (lane b2…0002) and a critical laneBlocked on the entry lane (b2…0001). When the board asks for raised alerts of major or worse at the *garage*, then at one lane, then only critical. Then the garage query returns both (a lane is inside its Place: subtree-inclusive), the lane query returns one, and the severityFloor query returns only the critical one. | F11: GET /v1/alerts → 200 GET /v1/alerts → 200 GET /v1/alerts → 200 | G11: =IF(F11="",0,LEN(F11)-LEN(SUBSTITUTE(F11,CHAR(10),""))+1)
A12: ALT-11 | B12: Wrong way at Riverside Lot: raised by the operator's own rule | C12: happy | D12: APX-ALT-03 | E12: Given a pickup enters Riverside Lot through the exit lane; the LPR system reports the read as accessEvent: entry on lane b2…0061. APX itself defines no wrong-way travel and never raises this alert (Part 13 §13.3a(6)), but wrongWayTravel stays in the registry as an operator-defined type. When the operator's own rules engine, which does care about lanes at this lot, raises wrongWayTravel with the Observation as relatedEntity, and the ops console lists today's wrong-way alerts for the lot and acknowledges the one it finds. Then the raise event carries the evidence reference, the type + place + since query finds it under the lot (the lane is in the subtree), and the acknowledge is 200. | F12: GET /v1/alerts → 200 POST /v1/alerts/e7000000-0000-4000-8000-000000000741/acknowledge → 200 | G12: =IF(F12="",0,LEN(F12)-LEN(SUBSTITUTE(F12,CHAR(10),""))+1)
A13: ALT-12 | B13: The guidance system sweeps level 2: the space-status family | C13: happy | D13: APX-ALT-03 | E13: Given the parking guidance system reconciles bay sensors against sessions every five minutes. When it finds a petrol car in the EV bay and raises iceInEvSpace with the Session as relatedEntity, and the board then lists everything raised at Lakeside since the sweep. Then 201, and a list holding the whole seeded space-status family: iceInEvSpace, occupiedWithoutCheckIn, wrongSpace, noCheckOut, overstay, each sourced on its Space, all info/warning. | F13: POST /v1/alerts → 201 GET /v1/alerts → 200 | G13: =IF(F13="",0,LEN(F13)-LEN(SUBSTITUTE(F13,CHAR(10),""))+1)
... A23: ALT-22 | B23: The shared refusals on the id-addressed Alerts routes | C23: security | D23: APX-CORE-05, APX-CORE-07, APX-ALT-01 | E23: Given a console with a transition body bug, a read-only wallboard, a tight polling loop, and an expired token. When each hits the read and transition routes. Then 400 invalid-request with errors[], 403 insufficient-scope, 429 rate-limited, and 401 unauthenticated, each declared on the route (Part 12 §12.3). | F23: POST /v1/alerts/e7000000-0000-4000-8000-000000000702/acknowledge → 400 POST /v1/alerts/e7000000-0000-4000-8000-000000000703/resolve → 400 POST /v1/alerts/e7000000-0000-4000-8000-000000000706/resolve → 403 GET /v1/alerts/e7000000-0000-4000-8000-000000000706 → 429 POST /v1/alerts/e7000000-0000-4000-8000-000000000706/acknowledge → 429 POST /v1/alerts/e7000000-0000-4000-8000-000000000706/resolve → 429 GET /v1/alerts/e7000000-0000-4000-8000-000000000706 → 401 POST /v1/alerts/e7000000-0000-4000-8000-000000000706/acknowledge → 401 POST /v1/alerts/e7000000-0000-4000-8000-000000000706/resolve → 401 | G23: =IF(F23="",0,LEN(F23)-LEN(SUBSTITUTE(F23,CHAR(10),""))+1)

Sheet apx-control
A1: ID | B1: Title | C1: Kind | D1: Annex A rows | E1: Scenario (Given / When / Then) | F1: Exchanges (request → status) | G1: Exchange count | H1: Open spec gap
A2: CTL-01 | B2: Vend the exit gate for a customer, confirmed by the sensor | C2: happy | D2: APX-CTL-01, APX-CTL-03, APX-CTL-05, APX-CTL-06 | E2: Given a driver at exit lane 2 whose ticket was resolved on the phone. When the agent vends the gate with an idempotency key, a reason, and a two-minute expiry. Then the server answers 202 with the command in accepted, and polling shows the full audit trail through succeeded with physicallyConfirmed, so the agent may say "the gate is open". | F2: POST /v1/commands → 202 GET /v1/commands/d1000000-0000-4000-8000-000000000101 → 200 | G2: =IF(F2="",0,LEN(F2)-LEN(SUBSTITUTE(F2,CHAR(10),""))+1)
A3: CTL-02 | B3: The console retries after a timeout: same key, same body | C3: edge | D3: APX-CTL-01 | E3: Given the 202 from CTL-01 never reached the console (network blip). When the console retries with the identical key and body. Then the server returns 200 with the ORIGINAL command, whatever state it has reached since; no second vend is issued. Polling an id that never existed is a 404. | F3: POST /v1/commands → 200 GET /v1/commands/d1000000-0000-4000-8000-0000000000ff → 404 | G3: =IF(F3="",0,LEN(F3)-LEN(SUBSTITUTE(F3,CHAR(10),""))+1)
A4: CTL-03 | B4: Same key reused for a different lane | C4: refusal | D4: APX-CTL-01, APX-CORE-05 | E4: Given a console bug reuses cc-7710-vend for a vend at the entry lane. When the body differs from the stored one. Then 409 idempotency-conflict; nothing is executed. | F4: POST /v1/commands → 409 | G4: =IF(F4="",0,LEN(F4)-LEN(SUBSTITUTE(F4,CHAR(10),""))+1)
A5: CTL-04 | B5: Malformed requests: no key, unknown type, throttled | C5: refusal | D5: APX-CTL-01, APX-CORE-05 | E5: Given three broken clients. When one omits Idempotency-Key, one sends a commandType that is in nobody's registry, and one exceeds the rate limit. Then each is refused with a registered problem type: the unknown type is invalid-request (Part 6 §6.1, Part 12 §12.4; F-CTL-01 fixed). | F5: POST /v1/commands → 400 POST /v1/commands → 400 POST /v1/commands → 429 | G5: =IF(F5="",0,LEN(F5)-LEN(SUBSTITUTE(F5,CHAR(10),""))+1)
A6: CTL-05 | B6: Perishable: the PARCS link is down for three minutes | C6: lifecycle | D6: APX-CTL-02, APX-CTL-03 | E6: Given the operator's link to the lane controller drops right after a vend is accepted with a 30-second expiry. When the link recovers three minutes later. Then the command has transitioned to expired, the history says why, and the gate did NOT open for whoever is in the lane now. A command submitted with an expiry already in the past is refused synchronously with 422 command-expired. | F6: POST /v1/commands → 202 GET /v1/commands/d1000000-0000-4000-8000-000000000102 → 200 POST /v1/commands → 422 | G6: =IF(F6="",0,LEN(F6)-LEN(SUBSTITUTE(F6,CHAR(10),""))+1)
A7: CTL-06 | B7: Cancel a hold-open that was issued by mistake | C7: lifecycle | D7: APX-CTL-04, APX-CTL-03 | E7: Given a supervisor issued holdGateOpen on the wrong lane. When they cancel it while it is still accepted. Then 200 with the command in cancelled, a new history entry naming who cancelled, and the gate never held. | F7: POST /v1/commands → 202 POST /v1/commands/d1000000-0000-4000-8000-000000000103/cancel → 200 | G7: =IF(F7="",0,LEN(F7)-LEN(SUBSTITUTE(F7,CHAR(10),""))+1)
A8: CTL-07 | B8: Cancel arrives after dispatch | C8: refusal | D8: APX-CTL-04 | E8: Given the vend from CTL-01 already reached the device. When a cancel is requested. Then 409 command-not-cancellable and the command's state is unchanged. Cancelling an id that does not exist has no declared response (F-CTL-06). | F8: POST /v1/commands/d1000000-0000-4000-8000-000000000101/cancel → 409 POST /v1/commands/d1000000-0000-4000-8000-0000000000ff/cancel → 404 | G8: =IF(F8="",0,LEN(F8)-LEN(SUBSTITUTE(F8,CHAR(10),""))+1)
A9: CTL-08 | B9: The device says no: rejected, and failed | C9: lifecycle | D9: APX-CTL-03, APX-CTL-05 | E9: Given the exit gate is in fault. When an agent vends it. Then the PARCS rejects the command (rejected, with the reason in the history). Later the fault clears, a second vend is dispatched, and the barrier motor times out: failed. In neither case is confirmationLevel above deviceAcknowledged, so an AI agent must tell the customer the vend was requested, not that the gate opened. | F9: POST /v1/commands → 202 GET /v1/commands/d1000000-0000-4000-8000-000000000104 → 200 POST /v1/commands → 202 GET /v1/commands/d1000000-0000-4000-8000-000000000105 → 200 | G9: =IF(F9="",0,LEN(F9)-LEN(SUBSTITUTE(F9,CHAR(10),""))+1)
A10: CTL-09 | B10: Lost ticket at the exit, fee from the deck | C10: happy | D10: APX-CTL-06, APX-CTL-08, APX-CTL-14 | E10: Given a driver at lane 2 with no ticket and no match candidates. When the agent issues lostTicket with the operator's method code. Then the command succeeds with a result naming the issued ticket, its session, and the fee (Part 6 §6.1a; F-CTL-02 fixed), and the lane inquiry shows the same ticket with amountDue equal to the deck's lostTicketFee line. | F10: GET /v1/lanes/b2000000-0000-4000-8000-000000000002/current → 200 POST /v1/commands → 202 GET /v1/commands/d1000000-0000-4000-8000-000000000106 → 200 GET /v1/lanes/b2000000-0000-4000-8000-000000000002/current → 200 | G10: =IF(F10="",0,LEN(F10)-LEN(SUBSTITUTE(F10,CHAR(10),""))+1)
A11: CTL-10 | B11: Lost ticket, but the deck has no lostTicketFee line | C11: refusal | D11: APX-CTL-08 | E11: Given the deck in force was pushed without a lostTicketFee line. When an agent issues lostTicket. Then the server refuses the POST synchronously with 422 lost-ticket-fee-undefined and creates no command: the deck is server-side state it can check before accepting (Part 6 §6.1; F-CTL-03 fixed). | F11: POST /v1/commands → 422 | G11: =IF(F11="",0,LEN(F11)-LEN(SUBSTITUTE(F11,CHAR(10),""))+1)
A12: CTL-11 | B12: Apply a cinema validation and watch the amount fall | C12: happy | D12: APX-CTL-06, APX-CTL-07 | E12: Given ticket T-1001 owes $9.00 at lane 2 and the driver saw a film. When the agent lists the place's providers, sees the cinema's benefit, and applies it. Then the lane's currentTicket.validations gains an entry with the actual amountReduced, and amountDue drops. | F12: GET /v1/validations/providers → 200 POST /v1/commands → 202 GET /v1/lanes/b2000000-0000-4000-8000-000000000002/current → 200 | G12: =IF(F12="",0,LEN(F12)-LEN(SUBSTITUTE(F12,CHAR(10),""))+1)
A13: CTL-12 | B13: A provider from the other garage | C13: refusal | D13: APX-CTL-07 | E13: Given Harbor Deck's hotel validates at Harbor Deck, not at Lakeside. When an agent applies it at Lakeside lane 2. Then 422 validation-provider-unknown; the provider list is authoritative. | F13: POST /v1/commands → 422 | G13: =IF(F13="",0,LEN(F13)-LEN(SUBSTITUTE(F13,CHAR(10),""))+1)
... A26: CTL-25 | B26: The shared refusals on every other Control route | C26: security | D26: APX-CORE-05, APX-CORE-07 | E26: Given the same four failure modes every client meets eventually. When they hit the id-addressed Control routes. Then each route answers with the shared response and a registered type: 403 for a target outside the grant or a missing scope, 429 when throttled, 401 on a dead token (Part 12 §12.3). A Lakeside token reads Harbor Deck's command, device, and lane, then tries to cancel with a read-only token: | F26: GET /v1/commands/d1000000-0000-4000-8000-000000000199 → 403 GET /v1/devices/c1000000-0000-4000-8000-000000000031 → 403 GET /v1/lanes/b2000000-0000-4000-8000-000000000003/current → 403 POST /v1/commands/d1000000-0000-4000-8000-000000000103/cancel → 403 GET /v1/commands/d1000000-0000-4000-8000-000000000101 → 429 POST /v1/commands/d1000000-0000-4000-8000-000000000103/cancel → 429 GET /v1/devices/c1000000-0000-4000-8000-000000000003 → 429 GET /v1/lanes/b2000000-0000-4000-8000-000000000002/current → 429 GET /v1/commands/d1000000-0000-4000-8000-000000000101 → 401 POST /v1/commands/d1000000-0000-4000-8000-000000000103/cancel → 401 GET /v1/devices/c1000000-0000-4000-8000-000000000003 → 401 GET /v1/lanes/b2000000-0000-4000-8000-000000000002/current → 401 | G26: =IF(F26="",0,LEN(F26)-LEN(SUBSTITUTE(F26,CHAR(10),""))+1)

Sheet apx-credentials
A1: ID | B1: Title | C1: Kind | D1: Annex A rows | E1: Scenario (Given / When / Then) | F1: Exchanges (request → status) | G1: Exchange count | H1: Open spec gap
A2: CRD-01 | B2: Issue a keycard for a new monthly parker | C2: happy | D2: APX-CRD-01, APX-CRD-05, APX-CRD-06 | E2: Given Maya Okafor signs a monthly contract starting January 1 and the front desk pulls an HID proximity card from stock. When the desk issues it with an idempotency key, a $25 deposit, and the validity window. Then the server answers 201 with the record in issued (nothing opens the gate yet), publishes apx.credentials.status.v1, and a read returns the same record with its identification — visible only because the token carries apx.credentials:*. | F2: POST /v1/credentials → 201 GET /v1/credentials/d6000000-0000-4000-8000-000000000101 → 200 | G2: =IF(F2="",0,LEN(F2)-LEN(SUBSTITUTE(F2,CHAR(10),""))+1)
A3: CRD-02 | B3: The desk console retries: same key, then the wrong key | C3: edge | D3: APX-CRD-01, APX-CORE-05 | E3: Given the 201 from CRD-01 was lost to a Wi-Fi drop at the front desk. When the console retries with the identical key and body, then a console bug reuses the key for a different card, then a third client forgets the header altogether. Then 200 with the ORIGINAL record (one card issued, not two), 409 idempotency-conflict, and 400 idempotency-key-required. | F3: POST /v1/credentials → 200 POST /v1/credentials → 409 POST /v1/credentials → 400 | G3: =IF(F3="",0,LEN(F3)-LEN(SUBSTITUTE(F3,CHAR(10),""))+1)
A4: CRD-03 | B4: Malformed record, unknown holder | C4: refusal | D4: APX-CRD-01, APX-CORE-05 | E4: Given two broken issue requests. When one omits credentialType and one names a RightHolder that does not exist. Then 400 invalid-request and 422 reference-unknown, both declared on the operation and both now registered in Part 12 and named in its descriptions (F-CRD-02 and F-CRD-01, fixed). | F4: POST /v1/credentials → 400 POST /v1/credentials → 422 | G4: =IF(F4="",0,LEN(F4)-LEN(SUBSTITUTE(F4,CHAR(10),""))+1)
A5: CRD-04 | B5: Ray's fob: issued at the desk, activated on collection, seen by a stock APDS lane | C5: lifecycle | D5: APX-CRD-01, APX-CRD-02, APX-CORE-02 | E5: Given Ray Delgado's monthly right starts today and the desk has a garage-remote fob ready. When the desk issues it at 09:00 and activates it at 09:05 when Ray collects it. Then the record goes issued → active, and the entry lane — an APDS-native client that only reads /rights/assigned — sees a CredentialAssigned whose identifier points at the CredentialRecord, without ever speaking APX. | F5: POST /v1/credentials → 201 POST /v1/credentials/d6000000-0000-4000-8000-000000000103/activate → 200 GET /rights/assigned → 200 | G5: =IF(F5="",0,LEN(F5)-LEN(SUBSTITUTE(F5,CHAR(10),""))+1)
A6: CRD-05 | B6: Activate twice, activate nothing | C6: refusal | D6: APX-CRD-01 | E6: Given the fob from CRD-04 is already active. When the desk double-clicks Activate, then a stale bookmark hits an id that never existed, on both the read and the activate route. Then 409 credential-transition-illegal (active is not issued), and 404 twice. | F6: POST /v1/credentials/d6000000-0000-4000-8000-000000000103/activate → 409 GET /v1/credentials/d6000000-0000-4000-8000-0000000000ff → 404 POST /v1/credentials/d6000000-0000-4000-8000-0000000000ff/activate → 404 | G6: =IF(F6="",0,LEN(F6)-LEN(SUBSTITUTE(F6,CHAR(10),""))+1)
A7: CRD-06 | B7: Suspended for non-payment until the 17th, denied at the gate, resumed by the clock | C7: lifecycle | D7: APX-CRD-01, APX-CRD-02, APX-CRD-04, APX-CRD-06 | E7: Given Ray's September invoice is unpaid on the 10th. When billing suspends the fob with until set to the 17th, Ray presents it at the entry lane that evening, and the 17th arrives. Then the record shows suspension, the stock APDS query on the AssignedRight comes back empty, the lane denies with credentialSuspended and the access event is published, and at the appointed instant the server resumes it with actor system and publishes the status event. | F7: POST /v1/credentials/d6000000-0000-4000-8000-000000000103/suspend → 200 GET /rights/assigned → 200 | G7: =IF(F7="",0,LEN(F7)-LEN(SUBSTITUTE(F7,CHAR(10),""))+1)
A8: CRD-07 | B8: Suspend and resume by hand, and the transitions that do not exist | C8: lifecycle | D8: APX-CRD-01, APX-CRD-02 | E8: Given Ray is travelling for a week and asks the desk to freeze the fob without an end date. When the desk suspends it on the 18th and resumes it on the 22nd, then clicks Resume again, and then tries to suspend a hangtag that was issued but never collected. Then 200, 200, 409 credential-transition-illegal (already active), and 409 credential-transition-illegal (issued cannot be suspended, only activated or revoked); an unknown id is 404 on both routes. | F8: POST /v1/credentials/d6000000-0000-4000-8000-000000000103/suspend → 200 POST /v1/credentials/d6000000-0000-4000-8000-000000000103/resume → 200 POST /v1/credentials/d6000000-0000-4000-8000-000000000103/resume → 409 POST /v1/credentials/d6000000-0000-4000-8000-000000000110/suspend → 409 POST /v1/credentials/d6000000-0000-4000-8000-0000000000ff/suspend → 404 POST /v1/credentials/d6000000-0000-4000-8000-0000000000ff/resume → 404 | G8: =IF(F8="",0,LEN(F8)-LEN(SUBSTITUTE(F8,CHAR(10),""))+1)
A9: CRD-08 | B9: Reported lost from active, stolen while suspended, and the states that cannot be lost | C9: lifecycle | D9: APX-CRD-01, APX-CRD-02 | E9: Given Maya calls at noon on the 19th: the keycard is gone (scenario 20). When the agent reports it lost; later, Northshore Plumbing's windshield transponder — suspended for an account balance — is reported stolen from a van; then someone tries report-lost on the uncollected hangtag and again on Maya's already-lost card. Then 200 (active → lost), 200 (suspended → lost), 409, 409, and 404 for an unknown id. From each lost instant the lane denies the credential. | F9: POST /v1/credentials/d6000000-0000-4000-8000-000000000101/report-lost → 200 POST /v1/credentials/d6000000-0000-4000-8000-000000000104/report-lost → 200 POST /v1/credentials/d6000000-0000-4000-8000-000000000110/report-lost → 409 POST /v1/credentials/d6000000-0000-4000-8000-000000000101/report-lost → 409 POST /v1/credentials/d6000000-0000-4000-8000-0000000000ff/report-lost → 404 | G9: =IF(F9="",0,LEN(F9)-LEN(SUBSTITUTE(F9,CHAR(10),""))+1)
A10: CRD-09 | B10: Replace the lost card from pre-encoded stock, in one call | C10: happy | D10: APX-CRD-01, APX-CRD-03, APX-CRD-06 | E10: Given Maya's card is lost and the front desk holds pre-encoded stock. When the agent replaces it, forfeiting the old deposit against the new one, and the console retries the same call after a timeout. Then 201 with the successor already active, inheriting holder, account, assigned right, places, and validity; the predecessor reads replaced with replacedBy and its deposit forfeited; the retry returns 200 with the SAME successor. The AssignedRight swapped cards in one AssignedRightUpdated. | F10: POST /v1/credentials/d6000000-0000-4000-8000-000000000101/replace → 201 GET /v1/credentials/d6000000-0000-4000-8000-000000000101 → 200 POST /v1/credentials/d6000000-0000-4000-8000-000000000101/replace → 200 | G10: =IF(F10="",0,LEN(F10)-LEN(SUBSTITUTE(F10,CHAR(10),""))+1)
A11: CRD-10 | B11: Everything replace refuses | C11: refusal | D11: APX-CRD-01, APX-CRD-03, APX-CORE-05 | E11: Given the replaced card from CRD-09, the hangtag revoked in CRD-12, the seasonal hangtag that expired in CRD-13, and the uncollected hangtag still in issued. When a replacement is requested on each, then on Ray's fob with a successor identification that is already live, then with the key from CRD-09 and a different body, then without a key, then on an id that does not exist. Then 409 credential-not-replaceable three times, 409 credential-transition-illegal for issued (F-CRD-04, fixed: §21.1 rule 1 now says so, and credential-not-replaceable is reserved for terminal states), 409 credential-identification-in-use, 409 idempotency-conflict, 400 idempotency-key-required, and 404. | F11: POST /v1/credentials/d6000000-0000-4000-8000-000000000101/replace → 409 POST /v1/credentials/d6000000-0000-4000-8000-000000000110/replace → 409 POST /v1/credentials/d6000000-0000-4000-8000-000000000112/replace → 409 POST /v1/credentials/d6000000-0000-4000-8000-000000000113/replace → 409 POST /v1/credentials/d6000000-0000-4000-8000-000000000103/replace → 409 POST /v1/credentials/d6000000-0000-4000-8000-000000000101/replace → 409 POST /v1/credentials/d6000000-0000-4000-8000-000000000103/replace → 400 POST /v1/credentials/d6000000-0000-4000-8000-0000000000ff/replace → 404 | G11: =IF(F11="",0,LEN(F11)-LEN(SUBSTITUTE(F11,CHAR(10),""))+1)
A12: CRD-11 | B12: 6 PM: the old card at the gate, and the next morning's question | C12: happy | D12: APX-CRD-02, APX-CRD-04, APX-CRD-05 | E12: Given the old card was taken off the AssignedRight at noon. When someone presents it at the entry lane at 18:02 and Maya asks the next morning whether anyone used it. Then the APDS-native lane finds no right carrying C-0048812 and denies; the server records the attempt with denialReason: credentialReplaced and publishes it; the history route returns newest-first, filters by outcome, pages, and 404s for an unknown credential. | F12: GET /v1/credentials/d6000000-0000-4000-8000-000000000101/access-events → 200 GET /v1/credentials/d6000000-0000-4000-8000-000000000101/access-events → 200 GET /v1/credentials/d6000000-0000-4000-8000-000000000101/access-events → 200 GET /v1/credentials/d6000000-0000-4000-8000-0000000000ff/access-events → 404 | G12: =IF(F12="",0,LEN(F12)-LEN(SUBSTITUTE(F12,CHAR(10),""))+1)
A13: CRD-12 | B13: Revoke: never collected, stolen, and twice is once too many | C13: lifecycle | D13: APX-CRD-01, APX-CRD-02, APX-CRD-06 | E13: Given a contractor hangtag issued on the 1st that nobody ever collected, and Northshore's transponder now lost with a police reference. When the desk revokes the hangtag from issued and the fleet desk revokes the transponder from lost, then a second revoke lands on each, and one on Maya's replaced card. Then 200, 200, and 409 credential-transition-illegal three times: revoked and replaced are terminal. The transponder's CredentialAssigned is gone from the fleet AssignedRight; an unknown id is 404. | F13: POST /v1/credentials/d6000000-0000-4000-8000-000000000110/revoke → 200 POST /v1/credentials/d6000000-0000-4000-8000-000000000104/revoke → 200 GET /rights/assigned → 200 POST /v1/credentials/d6000000-0000-4000-8000-000000000110/revoke → 409 POST /v1/credentials/d6000000-0000-4000-8000-000000000101/revoke → 409 POST /v1/credentials/d6000000-0000-4000-8000-0000000000ff/revoke → 404 | G13: =IF(F13="",0,LEN(F13)-LEN(SUBSTITUTE(F13,CHAR(10),""))+1)
... A26: CRD-25 | B26: Windows already over, and a card that activates itself | C26: edge | D26: APX-CRD-01, APX-CRD-06 | E26: Given a bulk import that still carries last season's contract, a billing batch that queues suspensions and replays them late, and a contractor hangtag the desk wants live the moment its window opens. When the import issues a card whose validity.end has passed, the batch suspends Maya's card until a time already gone, and the desk issues the hangtag with activateOnStart: true and a validity.start already past. Then 422 request-unprocessable twice, nothing written (F-CRD-11, fixed: §21.1 rule 7) — and 201 with the hangtag already active, activated by system at issue (F-CRD-06, fixed: §21.1 rule 6), materialized per §21.2 and published like any other transition. | F26: POST /v1/credentials → 422 POST /v1/credentials/d6000000-0000-4000-8000-000000000102/suspend → 422 POST /v1/credentials → 201 | G26: =IF(F26="",0,LEN(F26)-LEN(SUBSTITUTE(F26,CHAR(10),""))+1)

Sheet apx-data
A1: ID | B1: Title | C1: Kind | D1: Annex A rows | E1: Scenario (Given / When / Then) | F1: Exchanges (request → status) | G1: Exchange count | H1: Open spec gap
A2: DATA-01 | B2: A plain APDS client pulls the hierarchy, no APX anywhere | C2: happy | D2: APX-DATA-01, APX-DATA-07, APX-CORE-01, APX-CORE-02 | E2: Given the city platform's first integration is a stock APDS 4.1 client that has never heard of APX. When it lists places, reads the garage, and reads the garage at an older version. Then it observes pure APDS 4.1: a HierarchyElementList, a Place whose hierarchyElementReference carries the native Supply and DemandTable, and version 6 of the same element. No APX header, no APX parameter, no APX field in the response. | F2: GET /places → 200 GET /places/b1000000-0000-4000-8000-000000000001 → 200 GET /places/b1000000-0000-4000-8000-000000000001 → 200 | G2: =IF(F2="",0,LEN(F2)-LEN(SUBSTITUTE(F2,CHAR(10),""))+1)
A3: DATA-02 | B3: First sync with the coarse fallback: modified_since and tombstones | C3: happy | D3: APX-DATA-05, APX-DATA-07, APX-CORE-02 | E3: Given the city platform holds no cursor yet. When it pulls sessions changed since 17 September with the native modified_since (Part 5 §5.2 rule 3). Then a stock SessionList whose deletedReferences names the session purged on the 20th — APDS's own tombstone shape, before any APX parameter is used. | F3: GET /sessions → 200 | G3: =IF(F3="",0,LEN(F3)-LEN(SUBSTITUTE(F3,CHAR(10),""))+1)
A4: DATA-03 | B4: Switch to the cursor feed and drain it | C4: happy | D4: APX-DATA-03, APX-DATA-04, APX-DATA-01 | E4: Given the platform has finished its full pull and been handed cursor c:00041. When it asks /sessions for changes after that cursor. Then a ChangeFeedPage: change-mode items carrying identity plus only the changed fields, a tombstone, a new cursor, and next pointing at the immediately available second page; the second page ends with next: null, so the platform polls later with c:00043. | F4: GET /sessions → 200 GET /sessions → 200 | G4: =IF(F4="",0,LEN(F4)-LEN(SUBSTITUTE(F4,CHAR(10),""))+1)
A5: DATA-04 | B5: Mirroring the rate deck, with the negotiable flag riding inside | C5: happy | D5: APX-DATA-03, APX-DATA-01, APX-CORE-04 | E5: Given the operator's call platform needs the deck. When it pulls /rates for the garage in mode=full once, then in mode=change with the cursor. Then the full list carries the standard deck and the flat $20 table with its apds-ext:apx:ratepolicy@1.0 decoration, and the change page carries only the corrected line on v8. The full-mode RateTable validates once the data overlay drops the two phantom required members (erratum 004), and the decoration lives in the extensions member the overlay declares on every APDS entity (erratum 010). | F5: GET /rates → 200 GET /rates → 200 | G5: =IF(F5="",0,LEN(F5)-LEN(SUBSTITUTE(F5,CHAR(10),""))+1)
A6: DATA-05 | B6: The other two feed routes: places and assigned rights | C6: happy | D6: APX-DATA-03, APX-DATA-04 | E6: Given the owner's BI platform holds cursors for /places and /rights/assigned. When it polls both in mode=change. Then the places page carries one item — the garage with only its demand table changed — and the assigned-rights page carries the monthly holder's renewed expiry plus a tombstone for a cancelled permit. Each feed is its own class, its own cursor, its own ordering. | F6: GET /places → 200 GET /rights/assigned → 200 | G6: =IF(F6="",0,LEN(F6)-LEN(SUBSTITUTE(F6,CHAR(10),""))+1)
A7: DATA-06 | B7: The warehouse crashed mid-load: replay from the old cursor | C7: lifecycle | D7: APX-DATA-04 | E7: Given the BI loader wrote cursor c:00042 to disk only after committing the page — and died between the two. When it restarts and replays from the cursor it last persisted, c:00041. Then the server returns exactly the page it returned in DATA-03: same item, same tombstone, same next cursor. Replaying an issued cursor yields every change after it exactly once; the loader's idempotent upsert makes the duplicate harmless. | F7: GET /sessions → 200 | G7: =IF(F7="",0,LEN(F7)-LEN(SUBSTITUTE(F7,CHAR(10),""))+1)
A8: DATA-07 | B8: Back from a two-week outage: the cursor is too old | C8: refusal | D8: APX-DATA-05, APX-DATA-03 | E8: Given the city platform was down from 8 to 24 September and still holds cursor c:00007, issued on the 8th. When it presents it. Then 404 target-not-found — the server retains seven days, the cursor is sixteen days old — and the platform re-syncs with mode=full before taking a fresh cursor. The cursor is an APX parameter, so the 404 the data overlay declares on the feed routes is always a Problem (Part 5 §5.2). | F8: GET /sessions → 404 GET /sessions → 200 | G8: =IF(F8="",0,LEN(F8)-LEN(SUBSTITUTE(F8,CHAR(10),""))+1)
A9: DATA-08 | B9: A cursor from another filter set, and from another credential | C9: refusal | D9: APX-DATA-04, APX-DATA-05 | E9: Given cursor c:00043 was issued to city-platform for the unfiltered sessions feed. When the same credential presents it with a place filter added, and then owner-bi presents it verbatim. Then both are 404 target-not-found: a cursor is scoped to (class, credential, filter set) and never composes across them (§5.2 rule 5). Same 404 as DATA-07. | F9: GET /sessions → 404 GET /sessions → 404 | G9: =IF(F9="",0,LEN(F9)-LEN(SUBSTITUTE(F9,CHAR(10),""))+1)
A10: DATA-09 | B10: The city's grant grows: Marina Lot arrives as a grantAddition | C10: edge | D10: APX-DATA-06, APX-DATA-03, APX-DATA-04 | E10: Given the operator adds Marina Lot to the city platform's apx_places grant overnight. When the platform polls /places with its existing cursor. Then the first page after the change carries grantAdditions naming the new subtree root — the cursor does not retroactively cover its history — and the platform runs a mode=full pull for that subtree before trusting the feed for it. The next page has no grantAdditions. The subtree pull uses the native place filter the data overlay adds to /places (subtree-inclusive, as on /sessions). | F10: GET /places → 200 GET /places → 200 GET /places → 200 | G10: =IF(F10="",0,LEN(F10)-LEN(SUBSTITUTE(F10,CHAR(10),""))+1)
A11: DATA-10 | B11: The PARCS pushes a new session in full mode | C11: happy | D11: APX-DATA-01, APX-DATA-02, APX-CORE-03 | E11: Given a car takes ticket T-1101 at the entry lane. When lakeside-parcs posts the session with a client-supplied id and no APX-Update-Mode header (so full, stock APDS behaviour). Then 201 with APDS's ResponseStatus, and a read shows the server-assigned initiator. The header is declared on the native PUTs only; a create always carries full state (Part 5 §5.1). | F11: POST /sessions → 201 GET /sessions/c4000000-0000-4000-8000-000000000101 → 200 | G11: =IF(F11="",0,LEN(F11)-LEN(SUBSTITUTE(F11,CHAR(10),""))+1)
A12: DATA-11 | B12: The PARCS retries the same POST, and posts a broken one | C12: refusal | D12: APX-CORE-03, APX-DATA-01 | E12: Given the PARCS never saw the 201 from DATA-10 and retries. When it re-posts the same client-supplied id, and separately posts a session with no actualStart. Then 409 with the conflicting id listed in ids (APDS convention; APX-CORE-03), and 400. Both keep the APDS ResponseStatus shape; with Accept: application/problem+json the same 409 is the registered id-collision problem (Part 5 §5.1a). | F12: POST /sessions → 409 POST /sessions → 400 | G12: =IF(F12="",0,LEN(F12)-LEN(SUBSTITUTE(F12,CHAR(10),""))+1)
A13: DATA-12 | B13: Close the session with a change-mode PUT: absent means unchanged | C13: happy | D13: APX-DATA-02, APX-DATA-01 | E13: Given T-1101 exits at 21:40. When the PARCS sends APX-Update-Mode: change with identity, actualEnd, and the closed segment — nothing else. Then 200, and a read shows version 2 with the credentials and vehicle exactly as before: absent meant unchanged. The change-mode body validates as a ChangePayload (Part 5 §5.1a), not as the full native Session. | F13: PUT /sessions/c4000000-0000-4000-8000-000000000101 → 200 GET /sessions/c4000000-0000-4000-8000-000000000101 → 200 | G13: =IF(F13="",0,LEN(F13)-LEN(SUBSTITUTE(F13,CHAR(10),""))+1)
... A34: DATA-33 | B34: Stale cursors on every feed, and the refusals APDS forgot to declare | C34: refusal | D34: APX-DATA-05, APX-DATA-03, APX-DATA-01 | E34: Given the BI platform's cursors for places, rates, assigned rights, and observations all predate the 7-day window, and a PARCS that sends a broken observation, a duplicate observation, a broken rate table, a duplicate rate table, and an update to an assigned right that does not exist. Then 404 target-not-found on each feed (Part 5 §5.2 rule 2), and the APDS ResponseStatus 400/409/404 that the data overlay now declares on POST /observations, POST /rates, and PUT /rights/assigned/{id} (APX errata 005 and 012). | F34: GET /places → 404 GET /rates → 404 GET /rights/assigned → 404 GET /observations → 404 POST /observations → 400 POST /observations → 409 POST /rates → 400 POST /rates → 409 PUT /rights/assigned/e2000000-0000-4000-8000-0000000000fe → 404 | G34: =IF(F34="",0,LEN(F34)-LEN(SUBSTITUTE(F34,CHAR(10),""))+1)

Sheet apx-discovery
A1: ID | B1: Title | C1: Kind | D1: Annex A rows | E1: Scenario (Given / When / Then) | F1: Exchanges (request → status) | G1: Exchange count | H1: Open spec gap
A2: DSC-01 | B2: A client with nothing but a hostname | C2: happy | D2: APX-CORE-09, APX-CORE-06, APX-CORE-12 | E2: Given a new integrator who has been told only "api.lakeside-garage.example". When they fetch /.well-known/apx-configuration at the host root with no credentials. Then they get the token endpoint, the APDS version, the claimed classes, and the registry locations, and can start the OAuth2 client-credentials flow. Harbor Deck's own PARCS starter host answers the same request with the three-class minimum. Lakeside's document also says which edition and which registry versions it validates against, and which optional features it offers (Part 16 §16.1; F-DSC-05 and F-DSC-01 fixed — the members land in ApxConfiguration when the integrator points the component at the discovery domain schema). | F2: GET /.well-known/apx-configuration → 200 GET /.well-known/apx-configuration → 200 | G2: =IF(F2="",0,LEN(F2)-LEN(SUBSTITUTE(F2,CHAR(10),""))+1)
A3: DSC-02 | B3: The console bootstraps: token, then its own capability document | C3: happy | D3: APX-DSC-01, APX-DSC-02, APX-DSC-04, APX-CORE-06 | E3: Given the console has exchanged its client credentials at the token endpoint from DSC-01 and holds a JWT with apx_org a1…0001 and apx_places ["b1…0001"]. When it calls GET /v1/discovery. Then the document names the client, reflects the scopes, org, and places exactly, lists the classes the token can use (the host's eight minus apx-alerts and apx-lpr, which no scope reaches), the concrete endpoints, all fifteen command types including the two optional-feature commands the host supports, the topics it may subscribe to, and advisory limits. The response is private and cacheable for five minutes. | F3: GET /v1/discovery → 200 | G3: =IF(F3="",0,LEN(F3)-LEN(SUBSTITUTE(F3,CHAR(10),""))+1)
A4: DSC-03 | B4: Two clients, two documents | C4: happy | D4: APX-DSC-03, APX-DSC-01 | E4: Given CityPark Analytics holds a read-only token on both garages. When it calls the same GET /v1/discovery on the same host, a minute after the console did. Then its document differs in every credential-derived member: another client id and organisation, two place roots, only the data and event classes, no control endpoints, an explicitly empty commandTypes, and only the topics a data reader may take. | F4: GET /v1/discovery → 200 | G4: =IF(F4="",0,LEN(F4)-LEN(SUBSTITUTE(F4,CHAR(10),""))+1)
A5: DSC-04 | B5: The document is a promise, not advertising | C5: security | D5: APX-DSC-02, APX-CORE-07 | E5: Given the console's document from DSC-02 lists no /v1/alerts and no /v1/lpr/reads. When a console developer "just tries" both, and then uses a listed endpoint (POST /v1/commands) against Harbor Deck's exit lane. Then the two unlisted endpoints fail 403 insufficient-scope, and the listed one fails 403 insufficient-grant: soundness covers the endpoint, the grant still bounds the inputs. | F5: GET /v1/alerts → 403 GET /v1/lpr/reads → 403 POST /v1/commands → 403 | G5: =IF(F5="",0,LEN(F5)-LEN(SUBSTITUTE(F5,CHAR(10),""))+1)
A6: DSC-05 | B6: An endpoint of a class the host does not claim | C6: refusal | D6: APX-DSC-02 | E6: Given the host claims no apx-valet. When a valet-app developer who has the console credential calls the valet queue for Lakeside. Then 404 target-not-found: an endpoint of a class the server does not claim is not there, while an endpoint it implements but the token's scopes do not cover is 403 insufficient-scope (DSC-04). Part 9 §9.3a settles it and Part 16 §16.2 and APX-DSC-02 now say the same (F-DSC-02 fixed; no new problem type needed). | F6: GET /v1/valet/queue → 404 | G6: =IF(F6="",0,LEN(F6)-LEN(SUBSTITUTE(F6,CHAR(10),""))+1)
A7: DSC-06 | B7: The explicit wildcard, and the token with no places at all | C7: security | D7: APX-CORE-08, APX-DSC-01 | E7: Given two tokens minted the same morning: Lakeside's operations client with the deliberate apx_places: ["*"], and a trial IVR client whose registration forgot the claim entirely. When each calls discovery. Then the first document carries the single wildcard entry and every data and alert endpoint; the second reflects no places and, fail-closed, lists only what can succeed without one. A missing claim is reflected as places: [], never an absent member, and "callable" means callable for at least one target inside the granted places, so the place-targeting routes are left out (Part 16 §16.2; F-DSC-09 fixed). | F7: GET /v1/discovery → 200 GET /v1/discovery → 200 | G7: =IF(F7="",0,LEN(F7)-LEN(SUBSTITUTE(F7,CHAR(10),""))+1)
A8: DSC-07 | B8: Discovery without a usable token | C8: refusal | D8: APX-CORE-06 | E8: Given a script that calls /v1/discovery before it has fetched a token, and a dashboard whose token expired overnight. When each calls. Then 401 unauthenticated both times (Part 12; F-DSC-03 fixed). | F8: GET /v1/discovery → 401 GET /v1/discovery → 401 | G8: =IF(F8="",0,LEN(F8)-LEN(SUBSTITUTE(F8,CHAR(10),""))+1)
